<?xml version="1.0" ?>
<sdf version="1.8">
    <model name='robot_lidar'>
      <link name='base'>
        <pose>0.0 0.0 0.15000000000000002 0 -0 0</pose>
        <inertial>
          <mass>1.14395</mass>
          <inertia>
            <ixx>0.26164</ixx>
            <ixy>0</ixy>
            <ixz>0</ixz>
            <iyy>0.3416519</iyy>
            <iyz>0</iyz>
            <izz>0.161014</izz>
          </inertia>
        </inertial>
        <visual name='visual_base'>
          <geometry>
            <box>
              <size>0.42 0.31 0.18</size>
            </box>
          </geometry>
          <material>
            <ambient>0.5 0.5 1.0 1</ambient>
            <diffuse>0.5 0.5 1.0 1</diffuse>
            <specular>0.0 0.0 1.0 1</specular>
          </material>
        </visual>
        <collision name='collision_base'>
          <geometry>
            <box>
              <size>0.42 0.31 0.18</size>
            </box>
          </geometry>
        </collision>
      </link>

      <link name='drivewhl_l'>
        <pose>-0.12 0.18 0.06 1.5707 0 0</pose>
        <inertial>
          <mass>0.5</mass>
          <inertia>
            <ixx>0.00145833</ixx>
            <ixy>0</ixy>
            <ixz>0</ixz>
            <iyy>0.00145833</iyy>
            <iyz>0</iyz>
            <izz>0.0025</izz>
          </inertia>
        </inertial>
        <visual name='visual_drivewhl_l'>
          <geometry>
            <cylinder>
              <radius>0.1</radius>
              <length>0.04</length>
            </cylinder>
          </geometry>
          <material>
            <ambient>0.2 0.2 0.2 1</ambient>
            <diffuse>0.2 0.2 0.2 1</diffuse>
            <specular>0.2 0.2 0.2 1</specular>
          </material>
        </visual>
        <collision name='collision_drivewhl_l'>
          <geometry>
            <cylinder>
              <radius>0.1</radius>
              <length>0.04</length>
            </cylinder>
          </geometry>
        </collision>
      </link>

      <link name='drivewhl_r'>
        <pose>-0.12 -0.18 0.06 1.5707 0 0</pose>
        <inertial>
          <mass>2</mass>
          <inertia>
            <ixx>0.00145833</ixx>
            <ixy>0</ixy>
            <ixz>0</ixz>
            <iyy>0.00145833</iyy>
            <iyz>0</iyz>
            <izz>0.0025</izz>
          </inertia>
        </inertial>
        <visual name='visual_drivewhl_r'>
          <geometry>
            <cylinder>
              <radius>0.1</radius>
              <length>0.04</length>
            </cylinder>
          </geometry>
          <material>
            <ambient>0.2 0.2 0.2 1</ambient>
            <diffuse>0.2 0.2 0.2 1</diffuse>
            <specular>0.2 0.2 0.2 1</specular>
          </material>
        </visual>
        <collision name='collision_drivewhl_r'>
          <geometry>
            <cylinder>
              <radius>0.1</radius>
              <length>0.04</length>
            </cylinder>
          </geometry>
        </collision>
      </link>

      <link name='caster'>
        <pose>0.14 0.0 0.06 0 -0 0</pose>
        <inertial>
          <mass>0.5</mass>
          <inertia>
            <ixx>0.1</ixx>
            <ixy>0</ixy>
            <ixz>0</ixz>
            <iyy>0.1</iyy>
            <iyz>0</iyz>
            <izz>0.1</izz>
          </inertia>
        </inertial>
        <visual name='visual_caster'>
          <geometry>
            <sphere>
              <radius>0.06</radius>
            </sphere>
          </geometry>
          <material>
            <ambient>0.2 0.2 0.2 1</ambient>
            <diffuse>0.2 0.2 0.2 1</diffuse>
            <specular>0.2 0.2 0.2 1</specular>
          </material>
        </visual>
        <collision name='collision_caster'>
          <geometry>
            <sphere>
              <radius>0.06</radius>
            </sphere>
          </geometry>
        </collision>
      </link>

      <joint name='drivewhl_l_joint' type='revolute'>
        <parent>base</parent>
        <child>drivewhl_l</child>
        <axis>
          <xyz>0 0 1</xyz>
          <limit>
            <lower>-1.79769e+308</lower>
            <upper>1.79769e+308</upper>
          </limit>
        </axis>
      </joint>

      <joint name='drivewhl_r_joint' type='revolute'>
        <parent>base</parent>
        <child>drivewhl_r</child>
        <axis>
          <xyz>0 0 1</xyz>
          <limit>
            <lower>-1.79769e+308</lower>
            <upper>1.79769e+308</upper>
          </limit>
        </axis>
      </joint>

      <joint name='caster_wheel' type='ball'>
        <parent>base</parent>
        <child>caster</child>
      </joint>

      <link name="rod">
        <pose>0.0 0.0 0.29 0 -0 0</pose>
        <inertial>
          <mass>0.1</mass>
          <inertia>
            <ixx>0.26164</ixx>
            <ixy>0</ixy>
            <ixz>0</ixz>
            <iyy>0.3416519</iyy>
            <iyz>0</iyz>
            <izz>0.161014</izz>
          </inertia>
        </inertial>
        <visual name='visual_rod'>
          <geometry>
            <box>
              <size>0.04 0.04 0.1</size>
            </box>
          </geometry>
          <material>
            <ambient>0.5 0.5 1.0 1</ambient>
            <diffuse>0.5 0.5 1.0 1</diffuse>
            <specular>0.0 0.0 1.0 1</specular>
          </material>
        </visual>
        <collision name='collision_rod'>
          <geometry>
            <box>
              <size>0.04 0.04 0.1</size>
            </box>
          </geometry>
        </collision>
      </link>

      <joint name="rod_joint" type="fixed">
        <parent>base</parent>
        <child>rod</child>
      </joint>

      <link name="hor_thing">
        <pose>0.0 0.0 0.3 0 -0 0</pose>
        <inertial>
          <mass>0.1</mass>
          <inertia>
            <ixx>0.26164</ixx>
            <ixy>0</ixy>
            <ixz>0</ixz>
            <iyy>0.3416519</iyy>
            <iyz>0</iyz>
            <izz>0.161014</izz>
          </inertia>
        </inertial>
        <visual name='visual_hor_thing'>
          <geometry>
            <box>
              <size>0.04 0.31 0.04</size>
            </box>
          </geometry>
          <material>
            <ambient>0.5 0.5 1.0 1</ambient>
            <diffuse>0.5 0.5 1.0 1</diffuse>
            <specular>0.0 0.0 1.0 1</specular>
          </material>
        </visual>
        <collision name='collision_hor_thing'>
          <geometry>
            <box>
              <size>0.04 0.31 0.04</size>
            </box>
          </geometry>
        </collision>
      </link>

      <joint name="hor_thing_joint" type="fixed">
        <parent>rod</parent>
        <child>hor_thing</child>
      </joint>

      <link name="ver_thing">
        <pose>0.0 0.0 0.3 0 -0 0</pose>
        <inertial>
          <mass>0.1</mass>
          <inertia>
            <ixx>0.26164</ixx>
            <ixy>0</ixy>
            <ixz>0</ixz>
            <iyy>0.3416519</iyy>
            <iyz>0</iyz>
            <izz>0.161014</izz>
          </inertia>
        </inertial>
        <visual name='visual_ver_thing'>
          <geometry>
            <box>
              <size>0.42 0.04 0.04</size>
            </box>
          </geometry>
          <material>
            <ambient>0.5 0.5 1.0 1</ambient>
            <diffuse>0.5 0.5 1.0 1</diffuse>
            <specular>0.0 0.0 1.0 1</specular>
          </material>
        </visual>
        <collision name='collision_ver_thing'>
          <geometry>
            <box>
              <size>0.42 0.04 0.04</size>
            </box>
          </geometry>
        </collision>
      </link>

      <joint name="ver_thing_joint" type="fixed">
        <parent>rod</parent>
        <child>ver_thing</child>
      </joint>

      <link name="lidar_link">
        <pose>0 0 0.4 0 0 0</pose>
        <inertial>
          <mass>0.1</mass>
          <inertia>
            <ixx>0.000166667</ixx>
            <iyy>0.000166667</iyy>
            <izz>0.000166667</izz>
          </inertia>
        </inertial>
        <collision name="collision">
          <geometry>
            <box>
              <size>0.1 0.1 0.1</size>
            </box>
          </geometry>
        </collision>
        <visual name="visual">
          <geometry>
            <box>
              <size>0.1 0.1 0.1</size>
            </box>
          </geometry>
        </visual>
        <sensor name='gpu_lidar' type='gpu_lidar'>
          <pose>0 0 0 0 0 0</pose>
          <topic>scan</topic>
          <ignition_frame_id>robot_lidar/lidar_link</ignition_frame_id>
          <update_rate>10</update_rate>
          <lidar>
            <scan>
              <horizontal>
                <samples>640</samples>
                <resolution>1</resolution>
                <min_angle>-1.396263</min_angle>
                <max_angle>1.396263</max_angle>
              </horizontal>
              <vertical>
                <samples>1</samples>
                <resolution>1</resolution>
                <min_angle>0.0</min_angle>
                <max_angle>0.0</max_angle>
              </vertical>
            </scan>
            <range>
              <min>0.08</min>
              <max>10.0</max>
              <resolution>0.01</resolution>
            </range>
          </lidar>
          <visualize>true</visualize>
        </sensor>
      </link>

      <joint name='lidar_joint' type='fixed'>
        <parent>ver_thing</parent>
        <child>lidar_link</child>
      </joint>

      <link name="depth_cam_link">
        <pose>0 0 0.6 0 0 0</pose>
        <inertial>
          <mass>0.1</mass>
          <inertia>
            <ixx>0.000166667</ixx>
            <iyy>0.000166667</iyy>
            <izz>0.000166667</izz>
          </inertia>
        </inertial>
        <collision name="collision">
          <geometry>
            <box>
              <size>0.1 0.1 0.1</size>
            </box>
          </geometry>
        </collision>
        <visual name="visual">
          <geometry>
            <box>
              <size>0.1 0.1 0.1</size>
            </box>
          </geometry>
        </visual>
        <sensor name="depth" type="depth_camera">
          <ignition_frame_id>robot_lidar/depth_cam_link</ignition_frame_id>
          <pose>0 0.0175 0.0125 0 0 0</pose>
          <update_rate>6</update_rate>
          <always_on>0</always_on>
          <camera>
            <horizontal_fov>1.51843645</horizontal_fov>
            <image>
              <width>848</width>
              <height>480</height>
              <format>R_FLOAT32</format>
            </image>
            <clip>
              <near>0.1</near>
              <far>10</far>
            </clip>
            <lens>
              <intrinsics>
                <fx>421.61578369140625</fx>
                <fy>421.61578369140625</fy>
                <cx>422.2854309082031</cx>
                <cy>236.57237243652344</cy>
                <s>0</s>
              </intrinsics>
            </lens>
          </camera>
      </sensor>
      </link>

      <joint name='depth_cam_joint' type='fixed'>
        <parent>ver_thing</parent>
        <child>depth_cam_link</child>
      </joint>

       <link name="imu_cam_link">
        <pose>0 0 0.7 0 0 0</pose>
        <inertial>
          <mass>0.1</mass>
          <inertia>
            <ixx>0.000166667</ixx>
            <iyy>0.000166667</iyy>
            <izz>0.000166667</izz>
          </inertia>
        </inertial>
        <collision name="collision">
          <geometry>
            <box>
              <size>0.1 0.1 0.1</size>
            </box>
          </geometry>
        </collision>
        <visual name="visual">
          <geometry>
            <box>
              <size>0.1 0.1 0.1</size>
            </box>
          </geometry>
        </visual>
        <sensor name="imu_sensor" type="imu">
            <always_on>1</always_on>
            <update_rate>1</update_rate>
            <visualize>true</visualize>
            <topic>imu</topic>
        </sensor>
      </link>

      <joint name='imu_cam_joint' type='fixed'>
        <parent>ver_thing</parent>
        <child>imu_cam_link</child>
      </joint>


      <plugin
        filename="ignition-gazebo-diff-drive-system"
        name="ignition::gazebo::systems::DiffDrive">
        <left_joint>drivewhl_r_joint</left_joint>
        <right_joint>drivewhl_l_joint</right_joint>
        <wheel_separation>0.36</wheel_separation>
        <wheel_radius>0.1</wheel_radius>
        <odom_publish_frequency>1</odom_publish_frequency>
        <max_linear_acceleration>1</max_linear_acceleration>
        <min_linear_acceleration>-1</min_linear_acceleration>
        <max_angular_acceleration>2</max_angular_acceleration>
        <min_angular_acceleration>-2</min_angular_acceleration>
        <max_linear_velocity>0.5</max_linear_velocity>
        <min_linear_velocity>-0.5</min_linear_velocity>
        <max_angular_velocity>1</max_angular_velocity>
        <min_angular_velocity>-1</min_angular_velocity>
      </plugin>

       <!-- <plugin name="camera_plugin" filename="libgazebo_ros_openni_kinect.so">
          <baseline>0.2</baseline>
          <alwaysOn>true</alwaysOn>

          <updateRate>0.0</updateRate>
          <cameraName>camera_ir</cameraName>
          <imageTopicName>/camera/color/image_raw</imageTopicName>
          <cameraInfoTopicName>/camera/color/camera_info</cameraInfoTopicName>
          <depthImageTopicName>/camera/depth/image_raw</depthImageTopicName>
          <depthImageCameraInfoTopicName>/camera/depth/camera_info</depthImageCameraInfoTopicName>
          <pointCloudTopicName>/camera/depth/points</pointCloudTopicName>
          <frameName>depth_cam_link</frameName>
          <pointCloudCutoff>0.5</pointCloudCutoff>
          <pointCloudCutoffMax>3.0</pointCloudCutoffMax>
          <distortionK1>0</distortionK1>
          <distortionK2>0</distortionK2>
          <distortionK3>0</distortionK3>
          <distortionT1>0</distortionT1>
          <distortionT2>0</distortionT2>
          <CxPrime>0</CxPrime>
          <Cx>0</Cx>
          <Cy>0</Cy>
          <focalLength>0</focalLength>
          <hackBaseline>0</hackBaseline>
        </plugin> -->

      <plugin
        filename="gz-sim-joint-state-publisher-system"
        name="gz::sim::systems::JointStatePublisher">
      </plugin>

      <plugin
        filename="gz-sim-pose-publisher-system"
        name="gz::sim::systems::PosePublisher">
        <publish_link_pose>true</publish_link_pose>
        <use_pose_vector_msg>true</use_pose_vector_msg>
        <static_publisher>true</static_publisher>
        <static_update_frequency>1</static_update_frequency>
      </plugin>

      <plugin
        filename="gz-sim-odometry-publisher-system"
        name="gz::sim::systems::OdometryPublisher">
        <odom_frame>robot_lidar/odom</odom_frame>
        <robot_base_frame>robot_lidar</robot_base_frame>
      </plugin>
    </model>
</sdf>