<?xml version="1.0" ?>
<sdf version="1.8">
    <model name='diff_drive'>
      <link name='base'>
        <pose>0.0 0.0 0.15000000000000002 0 -0 0</pose>
        <inertial>
          <mass>1.14395</mass>
          <inertia>
            <ixx>0.26164</ixx>
            <ixy>0</ixy>
            <ixz>0</ixz>
            <iyy>0.3416519</iyy>
            <iyz>0</iyz>
            <izz>0.161014</izz>
          </inertia>
        </inertial>
        <visual name='visual_base'>
          <geometry>
            <box>
              <size>0.42 0.31 0.18</size>
            </box>
          </geometry>
          <material>
            <ambient>0.5 0.5 1.0 1</ambient>
            <diffuse>0.5 0.5 1.0 1</diffuse>
            <specular>0.0 0.0 1.0 1</specular>
          </material>
        </visual>
        <collision name='collision_base'>
          <geometry>
            <box>
              <size>0.42 0.31 0.18</size>
            </box>
          </geometry>
        </collision>
      </link>

      <link name='drivewhl_l'>
        <pose>-0.12 0.18 0.06 1.5707 0 0</pose>
        <inertial>
          <mass>0.5</mass>
          <inertia>
            <ixx>0.00145833</ixx>
            <ixy>0</ixy>
            <ixz>0</ixz>
            <iyy>0.00145833</iyy>
            <iyz>0</iyz>
            <izz>0.0025</izz>
          </inertia>
        </inertial>
        <visual name='visual_drivewhl_l'>
          <geometry>
            <cylinder>
              <radius>0.1</radius>
              <length>0.04</length>
            </cylinder>
          </geometry>
          <material>
            <ambient>0.2 0.2 0.2 1</ambient>
            <diffuse>0.2 0.2 0.2 1</diffuse>
            <specular>0.2 0.2 0.2 1</specular>
          </material>
        </visual>
        <collision name='collision_drivewhl_l'>
          <geometry>
            <cylinder>
              <radius>0.1</radius>
              <length>0.04</length>
            </cylinder>
          </geometry>
        </collision>
      </link>

      <link name='drivewhl_r'>
        <pose>-0.12 -0.18 0.06 1.5707 0 0</pose>
        <inertial>
          <mass>2</mass>
          <inertia>
            <ixx>0.00145833</ixx>
            <ixy>0</ixy>
            <ixz>0</ixz>
            <iyy>0.00145833</iyy>
            <iyz>0</iyz>
            <izz>0.0025</izz>
          </inertia>
        </inertial>
        <visual name='visual_drivewhl_r'>
          <geometry>
            <cylinder>
              <radius>0.1</radius>
              <length>0.04</length>
            </cylinder>
          </geometry>
          <material>
            <ambient>0.2 0.2 0.2 1</ambient>
            <diffuse>0.2 0.2 0.2 1</diffuse>
            <specular>0.2 0.2 0.2 1</specular>
          </material>
        </visual>
        <collision name='collision_drivewhl_r'>
          <geometry>
            <cylinder>
              <radius>0.1</radius>
              <length>0.04</length>
            </cylinder>
          </geometry>
        </collision>
      </link>

      <link name='caster'>
        <pose>0.14 0.0 0.06 0 -0 0</pose>
        <inertial>
          <mass>0.5</mass>
          <inertia>
            <ixx>0.1</ixx>
            <ixy>0</ixy>
            <ixz>0</ixz>
            <iyy>0.1</iyy>
            <iyz>0</iyz>
            <izz>0.1</izz>
          </inertia>
        </inertial>
        <visual name='visual_caster'>
          <geometry>
            <sphere>
              <radius>0.06</radius>
            </sphere>
          </geometry>
          <material>
            <ambient>0.2 0.2 0.2 1</ambient>
            <diffuse>0.2 0.2 0.2 1</diffuse>
            <specular>0.2 0.2 0.2 1</specular>
          </material>
        </visual>
        <collision name='collision_caster'>
          <geometry>
            <sphere>
              <radius>0.06</radius>
            </sphere>
          </geometry>
        </collision>
      </link>

      <joint name='drivewhl_l_joint' type='revolute'>
        <parent>base</parent>
        <child>drivewhl_l</child>
        <axis>
          <xyz>0 0 1</xyz>
          <limit>
            <lower>-1.79769e+308</lower>
            <upper>1.79769e+308</upper>
          </limit>
        </axis>
      </joint>

      <joint name='drivewhl_r_joint' type='revolute'>
        <parent>base</parent>
        <child>drivewhl_r</child>
        <axis>
          <xyz>0 0 1</xyz>
          <limit>
            <lower>-1.79769e+308</lower>
            <upper>1.79769e+308</upper>
          </limit>
        </axis>
      </joint>

      <joint name='caster_wheel' type='ball'>
        <parent>base</parent>
        <child>caster</child>
      </joint>

      <link name="rod">
        <pose>0.0 0.0 0.29 0 -0 0</pose>
        <inertial>
          <mass>0.1</mass>
          <inertia>
            <ixx>0.26164</ixx>
            <ixy>0</ixy>
            <ixz>0</ixz>
            <iyy>0.3416519</iyy>
            <iyz>0</iyz>
            <izz>0.161014</izz>
          </inertia>
        </inertial>
        <visual name='visual_rod'>
          <geometry>
            <box>
              <size>0.04 0.04 0.1</size>
            </box>
          </geometry>
          <material>
            <ambient>0.5 0.5 1.0 1</ambient>
            <diffuse>0.5 0.5 1.0 1</diffuse>
            <specular>0.0 0.0 1.0 1</specular>
          </material>
        </visual>
        <collision name='collision_rod'>
          <geometry>
            <box>
              <size>0.04 0.04 0.1</size>
            </box>
          </geometry>
        </collision>
      </link>

      <joint name="rod_joint" type="fixed">
        <parent>base</parent>
        <child>rod</child>
      </joint>

      <link name="hor_thing">
        <pose>0.0 0.0 0.3 0 -0 0</pose>
        <inertial>
          <mass>0.1</mass>
          <inertia>
            <ixx>0.26164</ixx>
            <ixy>0</ixy>
            <ixz>0</ixz>
            <iyy>0.3416519</iyy>
            <iyz>0</iyz>
            <izz>0.161014</izz>
          </inertia>
        </inertial>
        <visual name='visual_hor_thing'>
          <geometry>
            <box>
              <size>0.04 0.31 0.04</size>
            </box>
          </geometry>
          <material>
            <ambient>0.5 0.5 1.0 1</ambient>
            <diffuse>0.5 0.5 1.0 1</diffuse>
            <specular>0.0 0.0 1.0 1</specular>
          </material>
        </visual>
        <collision name='collision_hor_thing'>
          <geometry>
            <box>
              <size>0.04 0.31 0.04</size>
            </box>
          </geometry>
        </collision>
      </link>

      <joint name="hor_thing_joint" type="fixed">
        <parent>rod</parent>
        <child>hor_thing</child>
      </joint>

      <link name="ver_thing">
        <pose>0.0 0.0 0.3 0 -0 0</pose>
        <inertial>
          <mass>0.1</mass>
          <inertia>
            <ixx>0.26164</ixx>
            <ixy>0</ixy>
            <ixz>0</ixz>
            <iyy>0.3416519</iyy>
            <iyz>0</iyz>
            <izz>0.161014</izz>
          </inertia>
        </inertial>
        <visual name='visual_ver_thing'>
          <geometry>
            <box>
              <size>0.42 0.04 0.04</size>
            </box>
          </geometry>
          <material>
            <ambient>0.5 0.5 1.0 1</ambient>
            <diffuse>0.5 0.5 1.0 1</diffuse>
            <specular>0.0 0.0 1.0 1</specular>
          </material>
        </visual>
        <collision name='collision_ver_thing'>
          <geometry>
            <box>
              <size>0.42 0.04 0.04</size>
            </box>
          </geometry>
        </collision>
      </link>

      <joint name="ver_thing_joint" type="fixed">
        <parent>rod</parent>
        <child>ver_thing</child>
      </joint>

      <plugin
        filename="ignition-gazebo-diff-drive-system"
        name="ignition::gazebo::systems::DiffDrive">
        <left_joint>drivewhl_l_joint</left_joint>
        <right_joint>drivewhl_r_joint</right_joint>
        <wheel_separation>0.36</wheel_separation>
        <wheel_radius>0.1</wheel_radius>
        <odom_publish_frequency>1</odom_publish_frequency>
        <max_linear_acceleration>1000</max_linear_acceleration>
        <min_linear_acceleration>-1000</min_linear_acceleration>
        <max_angular_acceleration>2</max_angular_acceleration>
        <min_angular_acceleration>-2</min_angular_acceleration>
        <max_linear_velocity>1000</max_linear_velocity>
        <min_linear_velocity>-1000</min_linear_velocity>
        <max_angular_velocity>1000</max_angular_velocity>
        <min_angular_velocity>-1000</min_angular_velocity>
      </plugin>
    </model>
</sdf>
